Traceback (most recent call last):
  File "C:\Users\Kevin\AppData\Local\R-MINI~1\envs\jb-env\lib\site-packages\jupyter_cache\executors\utils.py", line 58, in single_nb_execution
    executenb(
  File "C:\Users\Kevin\AppData\Local\R-MINI~1\envs\jb-env\lib\site-packages\nbclient\client.py", line 1319, in execute
    return NotebookClient(nb=nb, resources=resources, km=km, **kwargs).execute()
  File "C:\Users\Kevin\AppData\Local\R-MINI~1\envs\jb-env\lib\site-packages\jupyter_core\utils\__init__.py", line 165, in wrapped
    return loop.run_until_complete(inner)
  File "C:\Users\Kevin\AppData\Local\R-MINI~1\envs\jb-env\lib\asyncio\base_events.py", line 649, in run_until_complete
    return future.result()
  File "C:\Users\Kevin\AppData\Local\R-MINI~1\envs\jb-env\lib\site-packages\nbclient\client.py", line 709, in async_execute
    await self.async_execute_cell(
  File "C:\Users\Kevin\AppData\Local\R-MINI~1\envs\jb-env\lib\site-packages\nbclient\client.py", line 1062, in async_execute_cell
    await self._check_raise_for_error(cell, cell_index, exec_reply)
  File "C:\Users\Kevin\AppData\Local\R-MINI~1\envs\jb-env\lib\site-packages\nbclient\client.py", line 918, in _check_raise_for_error
    raise CellExecutionError.from_cell_and_msg(cell, exec_reply_content)
nbclient.exceptions.CellExecutionError: An error occurred while executing the following cell:
------------------
import pandas as pd
import glob
import numpy as np
import matplotlib.pyplot as plt
import seaborn as sns
from IPython.display import display
import plotly.express as px
from plotly.offline import plot
from plotly.subplots import make_subplots
import plotly.graph_objects as go
from scipy.stats import chi2_contingency
from scipy import stats
import plotly.subplots as sp
from sklearn.experimental import enable_iterative_imputer
from sklearn.impute import IterativeImputer
import warnings
import json
from urllib.request import urlopen
with urlopen('https://gist.githubusercontent.com/john-guerra/43c7656821069d00dcbc/raw/be6a6e239cd5b5b803c6e7c2ec405b793a9064dd/Colombia.geo.json') as response:
    counties = json.load(response)
------------------


[1;31m---------------------------------------------------------------------------[0m
[1;31mModuleNotFoundError[0m                       Traceback (most recent call last)
Cell [1;32mIn[1], line 1[0m
[1;32m----> 1[0m [38;5;28;01mimport[39;00m[38;5;250m [39m[38;5;21;01mpandas[39;00m[38;5;250m [39m[38;5;28;01mas[39;00m[38;5;250m [39m[38;5;21;01mpd[39;00m
[0;32m      2[0m [38;5;28;01mimport[39;00m[38;5;250m [39m[38;5;21;01mglob[39;00m
[0;32m      3[0m [38;5;28;01mimport[39;00m[38;5;250m [39m[38;5;21;01mnumpy[39;00m[38;5;250m [39m[38;5;28;01mas[39;00m[38;5;250m [39m[38;5;21;01mnp[39;00m

[1;31mModuleNotFoundError[0m: No module named 'pandas'

